2018-11-29 15:22:56,776 ERROR: Exception on /index [POST] [in /home/kaori/Desktop/flasky/ven/lib/python3.6/site-packages/flask/app.py:1761]
Traceback (most recent call last):
  File "/home/kaori/Desktop/flasky/ven/lib/python3.6/site-packages/flask/app.py", line 2292, in wsgi_app
    response = self.full_dispatch_request()
  File "/home/kaori/Desktop/flasky/ven/lib/python3.6/site-packages/flask/app.py", line 1815, in full_dispatch_request
    rv = self.handle_user_exception(e)
  File "/home/kaori/Desktop/flasky/ven/lib/python3.6/site-packages/flask/app.py", line 1718, in handle_user_exception
    reraise(exc_type, exc_value, tb)
  File "/home/kaori/Desktop/flasky/ven/lib/python3.6/site-packages/flask/_compat.py", line 35, in reraise
    raise value
  File "/home/kaori/Desktop/flasky/ven/lib/python3.6/site-packages/flask/app.py", line 1813, in full_dispatch_request
    rv = self.dispatch_request()
  File "/home/kaori/Desktop/flasky/ven/lib/python3.6/site-packages/flask/app.py", line 1799, in dispatch_request
    return self.view_functions[rule.endpoint](**req.view_args)
  File "/home/kaori/Desktop/flasky/ven/lib/python3.6/site-packages/flask_login/utils.py", line 261, in decorated_view
    return func(*args, **kwargs)
  File "/home/kaori/Desktop/flasky/app/routes.py", line 14, in index
    if form.validate_on_submit():
  File "/home/kaori/Desktop/flasky/ven/lib/python3.6/site-packages/flask_wtf/form.py", line 101, in validate_on_submit
    return self.is_submitted() and self.validate()
  File "/home/kaori/Desktop/flasky/ven/lib/python3.6/site-packages/wtforms/form.py", line 310, in validate
    return super(Form, self).validate(extra)
  File "/home/kaori/Desktop/flasky/ven/lib/python3.6/site-packages/wtforms/form.py", line 152, in validate
    if not field.validate(self, extra):
  File "/home/kaori/Desktop/flasky/ven/lib/python3.6/site-packages/wtforms/fields/core.py", line 206, in validate
    stop_validation = self._run_validation_chain(form, chain)
  File "/home/kaori/Desktop/flasky/ven/lib/python3.6/site-packages/wtforms/fields/core.py", line 226, in _run_validation_chain
    validator(form, self)
TypeError: __init__() takes from 1 to 2 positional arguments but 3 were given
2018-11-29 15:23:54,070 INFO: Microblog startup [in /home/kaori/Desktop/flasky/app/__init__.py:48]
2018-11-29 15:24:03,803 ERROR: Exception on /index [POST] [in /home/kaori/Desktop/flasky/ven/lib/python3.6/site-packages/flask/app.py:1761]
Traceback (most recent call last):
  File "/home/kaori/Desktop/flasky/ven/lib/python3.6/site-packages/flask/app.py", line 2292, in wsgi_app
    response = self.full_dispatch_request()
  File "/home/kaori/Desktop/flasky/ven/lib/python3.6/site-packages/flask/app.py", line 1815, in full_dispatch_request
    rv = self.handle_user_exception(e)
  File "/home/kaori/Desktop/flasky/ven/lib/python3.6/site-packages/flask/app.py", line 1718, in handle_user_exception
    reraise(exc_type, exc_value, tb)
  File "/home/kaori/Desktop/flasky/ven/lib/python3.6/site-packages/flask/_compat.py", line 35, in reraise
    raise value
  File "/home/kaori/Desktop/flasky/ven/lib/python3.6/site-packages/flask/app.py", line 1813, in full_dispatch_request
    rv = self.dispatch_request()
  File "/home/kaori/Desktop/flasky/ven/lib/python3.6/site-packages/flask/app.py", line 1799, in dispatch_request
    return self.view_functions[rule.endpoint](**req.view_args)
  File "/home/kaori/Desktop/flasky/ven/lib/python3.6/site-packages/flask_login/utils.py", line 261, in decorated_view
    return func(*args, **kwargs)
  File "/home/kaori/Desktop/flasky/app/routes.py", line 14, in index
    if form.validate_on_submit():
  File "/home/kaori/Desktop/flasky/ven/lib/python3.6/site-packages/flask_wtf/form.py", line 101, in validate_on_submit
    return self.is_submitted() and self.validate()
  File "/home/kaori/Desktop/flasky/ven/lib/python3.6/site-packages/wtforms/form.py", line 310, in validate
    return super(Form, self).validate(extra)
  File "/home/kaori/Desktop/flasky/ven/lib/python3.6/site-packages/wtforms/form.py", line 152, in validate
    if not field.validate(self, extra):
  File "/home/kaori/Desktop/flasky/ven/lib/python3.6/site-packages/wtforms/fields/core.py", line 206, in validate
    stop_validation = self._run_validation_chain(form, chain)
  File "/home/kaori/Desktop/flasky/ven/lib/python3.6/site-packages/wtforms/fields/core.py", line 226, in _run_validation_chain
    validator(form, self)
TypeError: __init__() takes from 1 to 2 positional arguments but 3 were given
2018-11-29 15:27:27,364 INFO: Microblog startup [in /home/kaori/Desktop/flasky/app/__init__.py:48]
